# 예외처리

## 프로그램 오류

프로그램 실행 중 오작동을 하거나 비정상적으로 종료되는 원인을 에러 또는 오류라고 함

* ```컴파일 에러``` : 컴파일 시 발생하는 에러
* ```런타임 에러``` : 프로그램 실행 시에 발생하는 에러
* ```논리적 에러``` : 실행은 되지만, 의도와 다르게 동작하는 것

## 예외 클래스의 계층구조
![image](https://user-images.githubusercontent.com/97823928/161370629-f2ad6098-b829-4723-91a5-3f4efe149528.png) 

모든 클래스의 조상은 Object 클래스, 예외의 최고 조상은 Exception클래스

## 예외처리하기 - try-catch문

```예외처리```: 프로그램 실행 시 발생할 수 있는 예오의 발생에 대비한 코드를 작성하는 것 
* 프로그램의 비정상 종료를 막고, 정상적인 실행상태를 유지하는 것을 목적으로 함

```java
try {
    // 예외가 발생할 가능성이 있는 문장을 넣음    
} catch (Exception e1) {
    // 예외 e1 발생 시, 이를 처리하기 위한 문장을 넣음
} catch (Exception e2) {
    // 예외 e2 발생 시, 이를 처리하기 위한 문장을 넣음
}
```

#### 예제

```java
class ExceptionEx3 {
    public static void main(String[] args) {
        int number = 100;
        int result = 0;
        
        for(int = 0; i < 10; i++) {
            try {
                result = nuber / (int) (Math.random() * 10); // 0~9 사이의 임의의 정수로 나누어줌
                System.out.println(result);
            } catch (ArithmeticException e) {
                System.out.println("0"); // 해당 예외가 발생하면 실행되는 코드 
            }
        }
    }
}
```
* 위의 예제는 해당 에러가 발생했을 경우 0을 단순히 화면에 출력함
* 만약 try-catch문으로 예외처리를 하지 않으면, 0으로 나눠지는 순간 프로그램이 비정상적으로 종료될 것임

## try-catch문에서의 흐름

#### try블럭 내에서 예외가 발생한 경우
* 발생한 예외와 일치하는 catch 블럭이 있는지 확인
* 일치하는 catch블럭을 찾으면, 그 catch 블럭 내의 문장들을 수행 후 전체 try-catch문을 ㅏ져나가서 그 다음 문장을 계속해서 수행
* 만약 일치하는 catch블럭이 없으면 예외는 처리되지 못함

#### try블럭 내에서 예외가 발생하지 않은 경우
* catch블럭을 거치지 않고 전체 try문과 try-catch문 밖의 문장들을 수행

```java
class ExceptionEx5 {
    public static void main(String[] args) {
        System.out.println(1);
        System.out.println(2);
        try {
            System.out.println(3);
            System.out.println(0/0); //여기서 예외 발생
            System.out.println(4); // 출력되지 않음
        } catch (ArithmeticException ae) {
            System.out.println(5);
        }
        System.out.println(6);
    }
}
```
```java
//출력결과
1
2
3
5
6
```
* try 블럭에서 예외가 발생하면, 예외가 발생한 위치 이후의 try 블럭 내의 문장들은 수행되지 않음!!
* try 블럭에 포함시킬 코드의 범위를 잘 결정하자!

## 예외의 발생과 catch블럭

* 예외가 발생하면 발생한 예외에 해당하는 클래스의 인스턴스가 생성됨
* → 첫번째 catch블럭부터 차례로 내려감
* → catch블럭의 괄호()내에 선언된 참조변수의 종류와 생성된 예외클래스의 인스턴스에 instanceof 연산자를 이용하여 검사
* → 검사결과가 true인 catch블럭을 만날 때까지 검사는 계속.. (없으면 예외처리되지 않음)

```java
class ExceptionEx7 {
    public static void main(String[] args) {
        System.out.println(1);
        System.out.println(2);
        try {
            System.out.println(3);
            System.out.println(0/0); //여기서 예외 발생
            System.out.println(4); // 출력되지 않음
        } catch (ArithmeticException ae) {
            if (ae instance of ArithmeticException) 
                System.out.println("true");
            System.out.println("ArithmeticException");
        } catch (Exception e) { // 여기서 ArithmeticException을 제외한 모든 예외가 처리됨
            System.out.println("Exception");
        }
        System.out.println(6);
    }
}
```
* 모든 예외 클래스는 Exception클래스의 자손이므로 catch 블럭의 괄호에 Exception르래스 타입의 참조변수를 선언해 놓으면 어떤 종류의 예외가 발생하더라도 이 catch문에 의해서 처리됨
* 위의 예제는 첫 번째 검사헤엇 일치하는 catch블럭을 찾았기 떄문에 두 번째 catch 블럭은 검사하지 않음
* 그러므로 만일 ArithmeticException 아닌 다른 종류의 예외가 발생한 경우 두번쨰 catch블럭에서 처리됨

### printStackTrace()와 getMessage()
* ```printStackTrace()``` : 예외발생 당시의 호출스택에 있었던 메서드의 정보와 예외 메세지를 화면에 출력
* ```getMessage()``` : 발생한 예외클래스의 인스턴스에 저장된 메세지를 얻을 수 있음

### 멀티 catch 블럭

catch블럭을 '|' 기호를 통해 하나의 블럭으로 합칠 수 있게 됨

```java
try {
    ...
} catch (Exception e) {
    e.printStackTrace();
} catch (Exception e2) {
    e2.printStackTrace();
}
```

위의 코드를 멀티블럭을 이용하여 합쳐보자!

```java
try {
    ...
} catch (ExceptionA | ExceptionB e) {
    e.printStackTrace();
}
```

#### 주의점
* 만일 멀티 catch블럭의 '|' 기호로 연결된 예외 클래스가 조상과 자손의 관계에 있다면 컴파일 에러 발생
* why? 두 예외 클래스가 조상과 자손의 관계에 있다면 조상 클래스만 써주는 것과 같기 때문에!

## 예외 발생시키기

프로그래머는 ```throw``` 키워드를 통해 고의로 예외를 발생시킬 수 있음!
1. 먼저 new를 이용하여 발생시키려는 예외 클래스의 객체를 만든다
* ```Exception e = new Exception("고의로 발생시킴");```
2. 키워드 throw를 이용해서 예외를 발생시킨다
* ```throw e;```
* ```throw new Exception("고의로 발생시킴")```처럼 한 줄로 줄일 수 있음

#### 예제
```java
class ExceptionEx10 {
    public static void main(String[] args) {
        throw new Exception(); //Exception을 고의로 발생
    }
}
```
* 이 예제를 작성 후 컴파일을 하면 ```unreported exception java.lang.Exception' must be caught or declared to be thrown ... ```같은 에러가 발생하면서 컴파일이 되지 않음
* 예외처리가 되어야할 부분에 예외처리가 되어있지 않다는 것이다!!

```java
class ExceptionEx11 {
    public static void main(String[] args) {
        throw new RuntimeException();
    }
}
```
* 반면 이 예제는 예외처리를 하지않았음에도 컴파일이 성공적으로 된다
* why? RuntimeException클래스는 프로그래머가 실수로 발생시키는 에러기 때문에 예외처리를 강제하지 않기 때문
* 결국 컴파일러가 예외처리를 확인하지 않는 RuntimeException같은 클래스들은 unchecked예외라고 부름

## 메서드에 예외 선언하기

```java
void method() throws Exception1, Exception2, ... {
    //메서드 내용
}
```

* 예외를 메서드의 throws에 명시하는 것은 예외를 처리하는 것이 아님!
* 그저 자신을 호출한 메서드에게 예외를 전달하여 예외처리를 떠맡기는 것

```java
class ExceptionEx12 {
    public static void main(String[] args) throws Exception {
        method1(); // 같은 클래스내의 static 멤버이므로 객체생성없이 직접 호출 가능
        // 3. main에서도 예외처리가 없으므로 비정상적으로 종료됨
    }
    
    static void method1() throws Exception {
        method2(); // 2. method1()에서도 예외처리 되지 않음 -> main으로 예외를 넘김
    }
    
    static void method2() throws Exception {
        throw new Exception(); // 1. 여기서 예외가 강제적으로 발생, but 예외처리x -> 자신을 호출한 method1()에게 넘김
    }
}
```
* 예외를 전달받은 메서드가 또다시 자신을 호출한 메서드에게 전달할 수 있음
* 제일 마지막에 있는 main메서드에서도 예외가 처리되지 않으면 프로그램 전체가 종료됨
* 결국 어디선가 try-catch문으로 예외처리를 해주어야 함

## finally 블럭

```java
try {
    // 예외가 발생할 가능성이 있는 문장을 넣음    
} catch (Exception e1) {
    // 예외 e1 발생 시, 이를 처리하기 위한 문장을 넣음
} finally {
    // 예외의 발생여부와 관계없이 항상 수행되어야하는 문장들을 넣음
}
```
* 예외 발생 O : try → catch → finally
* 예외 발생 X : try → fianlly

## 자동 자원 반환 - try-with-resources문

#### 예제 1

```java
try {
    fis = new FileInputStream("score.dat");
    dis = new DataInputStream(fis); // 파일로부터 데이터를 읽어옴
} catch (IOException ie) {
    ie.printStackTrace();
} finally {
    dis.close(); // 도중에 예외가 발생하더라도 DataInputStream이 닫히도록 close()를 finally블럭안에 넣음
}
```

하지만! 진짜 문제는 close()가 예외를 발생시킬 수 있다는 것.. → try-catch문으로 예외처리를 해주어야 함

#### 예제2 : try-catch문

```java
try {
    fis = new FileInputStream("score.dat");
    dis = new DataInputStream(fis);
} catch (IOException ie) {
    ie.printStackTrace();
} finally {
    try {
        if (dis != null)
            dis.close();
    } catch (IOException ie) {
        ie.printStackTrace();
    } 
}
```
* finally블럭 안에 try-catch문을 추가하여 close()에서 발생할 수 있는 예외를 처리하도록 변경
* 하지만 코드가 복잡해짐과 동시에,, try블럭과 finally블럭 모두에서 예외가 발생하면 try블럭의 예외는 무시되는 문제가 발생

#### 예제3 : try-with-resources문

```java
try (fis = new FileInputStream("score.dat");
     dis = new DataInputStream(fis)) {
     ...
} catch ( ... ) {
     ...
} catch ( ... ) {
   
}
```
→ try문의 () 안에 객체를 생성하는 문장을 넣으면, 이 객체는 따로 close()를 호출하지 않아도 try문을 벗어나는 순간 자동적으로 close()가 호출됨!

## 예외 되던지기

예외 되던지기는 하나의 예외에 대해서 예외가 발생한 메서드와 이를 호출한 메서드 양쪽 모두에서 처리해줘야 할 작업이 있을 떄 사용

#### 예제1

```java
class Exception17 {
    public static void main(String[] args) {
        try {
            method1(); // 1. method1 호출
        } catch (Exception e) {
            System.out.println("main메서드에서 예외가 처리되었습니다."); // 4. 예외처리 됨 
        }
    }
    
    static void method1() throws Exception {
        try {
            throw new Exception(); // 2. 예외를 던짐 
        } catch (Exception e) {
            System.out.println("method1메서드에서 예외가 처리되었습니다.");
            throw e; // 3. 또 예외를 발생 시킴 
        } finally {
            System.out.println("method1()의 finally 블럭이 실행되었습니다.");
        }
    }
}
```

#### 예제 2

: 반환값이 있는 return문의 경우 catch블럭에서도 return문이 있어야 함

```java
class Exception17 {
    public static void main(String[] args) {
        try {
            method1();
        } catch (Exception e) {
            System.out.println("main메서드에서 예외가 처리되었습니다.");
        }
    }
    
    static void method1() throws Exception {
       try {
           System.out.println("method1()이 호출되었습니다.");
           return 0; // 현재 실행 중인 메서드를 종료
       } catch (Exception e) {
           e.printStackTrace();
           return 1; // catch블럭 내에서도 return문이 필요
           throw new Exception(); 
       } finally {
           System.out.println("method1()의 finally 블럭이 실행되었습니다.");
       }
    }
}
```

#### 예제3
: catch 블럭에서 예외 되던지기를 해서 호출한 메서드로 예외를 전달하면 return문이 없어도 됨

```java
class Exception17 {
    public static void main(String[] args) {
        try {
            method1();
        } catch (Exception e) {
            System.out.println("main메서드에서 예외가 처리되었습니다.");
        }
    }
    
    static void method1() throws Exception {
       try {
           System.out.println("method1()이 호출되었습니다.");
           return 0; // 현재 실행 중인 메서드를 종료
       } catch (Exception e) {
           e.printStackTrace();
           throw new Exception(); // return문 대신 예외를 호출한 메서드로 
       } finally {
           System.out.println("method1()의 finally 블럭이 실행되었습니다.");
       }
    }
}
```

